/Users/ceyhun/payviya-api/venv/lib/python3.13/site-packages/pydantic/_internal/_config.py:373: UserWarning: Valid config keys have changed in V2:
* 'orm_mode' has been renamed to 'from_attributes'
  warnings.warn(message, UserWarning)
Traceback (most recent call last):
  File "<frozen runpy>", line 198, in _run_module_as_main
  File "<frozen runpy>", line 88, in _run_code
  File "/Users/ceyhun/payviya-api/venv/lib/python3.13/site-packages/uvicorn/__main__.py", line 4, in <module>
    uvicorn.main()
    ~~~~~~~~~~~~^^
  File "/Users/ceyhun/payviya-api/venv/lib/python3.13/site-packages/click/core.py", line 1161, in __call__
    return self.main(*args, **kwargs)
           ~~~~~~~~~^^^^^^^^^^^^^^^^^
  File "/Users/ceyhun/payviya-api/venv/lib/python3.13/site-packages/click/core.py", line 1082, in main
    rv = self.invoke(ctx)
  File "/Users/ceyhun/payviya-api/venv/lib/python3.13/site-packages/click/core.py", line 1443, in invoke
    return ctx.invoke(self.callback, **ctx.params)
           ~~~~~~~~~~^^^^^^^^^^^^^^^^^^^^^^^^^^^^^
  File "/Users/ceyhun/payviya-api/venv/lib/python3.13/site-packages/click/core.py", line 788, in invoke
    return __callback(*args, **kwargs)
  File "/Users/ceyhun/payviya-api/venv/lib/python3.13/site-packages/uvicorn/main.py", line 413, in main
    run(
    ~~~^
        app,
        ^^^^
    ...<45 lines>...
        h11_max_incomplete_event_size=h11_max_incomplete_event_size,
        ^^^^^^^^^^^^^^^^^^^^^^^^^^^^^^^^^^^^^^^^^^^^^^^^^^^^^^^^^^^^
    )
    ^
  File "/Users/ceyhun/payviya-api/venv/lib/python3.13/site-packages/uvicorn/main.py", line 580, in run
    server.run()
    ~~~~~~~~~~^^
  File "/Users/ceyhun/payviya-api/venv/lib/python3.13/site-packages/uvicorn/server.py", line 66, in run
    return asyncio.run(self.serve(sockets=sockets))
           ~~~~~~~~~~~^^^^^^^^^^^^^^^^^^^^^^^^^^^^^
  File "/usr/local/Cellar/python@3.13/3.13.3/Frameworks/Python.framework/Versions/3.13/lib/python3.13/asyncio/runners.py", line 195, in run
    return runner.run(main)
           ~~~~~~~~~~^^^^^^
  File "/usr/local/Cellar/python@3.13/3.13.3/Frameworks/Python.framework/Versions/3.13/lib/python3.13/asyncio/runners.py", line 118, in run
    return self._loop.run_until_complete(task)
           ~~~~~~~~~~~~~~~~~~~~~~~~~~~~~^^^^^^
  File "uvloop/loop.pyx", line 1518, in uvloop.loop.Loop.run_until_complete
  File "/Users/ceyhun/payviya-api/venv/lib/python3.13/site-packages/uvicorn/server.py", line 70, in serve
    await self._serve(sockets)
  File "/Users/ceyhun/payviya-api/venv/lib/python3.13/site-packages/uvicorn/server.py", line 77, in _serve
    config.load()
    ~~~~~~~~~~~^^
  File "/Users/ceyhun/payviya-api/venv/lib/python3.13/site-packages/uvicorn/config.py", line 435, in load
    self.loaded_app = import_from_string(self.app)
                      ~~~~~~~~~~~~~~~~~~^^^^^^^^^^
  File "/Users/ceyhun/payviya-api/venv/lib/python3.13/site-packages/uvicorn/importer.py", line 19, in import_from_string
    module = importlib.import_module(module_str)
  File "/usr/local/Cellar/python@3.13/3.13.3/Frameworks/Python.framework/Versions/3.13/lib/python3.13/importlib/__init__.py", line 88, in import_module
    return _bootstrap._gcd_import(name[level:], package, level)
           ~~~~~~~~~~~~~~~~~~~~~~^^^^^^^^^^^^^^^^^^^^^^^^^^^^^^
  File "<frozen importlib._bootstrap>", line 1387, in _gcd_import
  File "<frozen importlib._bootstrap>", line 1360, in _find_and_load
  File "<frozen importlib._bootstrap>", line 1331, in _find_and_load_unlocked
  File "<frozen importlib._bootstrap>", line 935, in _load_unlocked
  File "<frozen importlib._bootstrap_external>", line 1026, in exec_module
  File "<frozen importlib._bootstrap>", line 488, in _call_with_frames_removed
  File "/Users/ceyhun/payviya-api/app/main.py", line 16, in <module>
    from app.api.v1.router import api_router
  File "/Users/ceyhun/payviya-api/app/api/v1/router.py", line 3, in <module>
    from app.api.v1.endpoints import campaigns, recommendations, banks, admin, mock_bank_api, auth, users
  File "/Users/ceyhun/payviya-api/app/api/v1/endpoints/users.py", line 150, in <module>
    @router.delete("/me/cards/{card_id}", status_code=204)
     ~~~~~~~~~~~~~^^^^^^^^^^^^^^^^^^^^^^^^^^^^^^^^^^^^^^^^
  File "/Users/ceyhun/payviya-api/venv/lib/python3.13/site-packages/fastapi/routing.py", line 994, in decorator
    self.add_api_route(
    ~~~~~~~~~~~~~~~~~~^
        path,
        ^^^^^
    ...<23 lines>...
        generate_unique_id_function=generate_unique_id_function,
        ^^^^^^^^^^^^^^^^^^^^^^^^^^^^^^^^^^^^^^^^^^^^^^^^^^^^^^^^
    )
    ^
  File "/Users/ceyhun/payviya-api/venv/lib/python3.13/site-packages/fastapi/routing.py", line 933, in add_api_route
    route = route_class(
        self.prefix + path,
    ...<24 lines>...
        generate_unique_id_function=current_generate_unique_id,
    )
  File "/Users/ceyhun/payviya-api/venv/lib/python3.13/site-packages/fastapi/routing.py", line 507, in __init__
    assert is_body_allowed_for_status_code(status_code), (
           ~~~~~~~~~~~~~~~~~~~~~~~~~~~~~~~^^^^^^^^^^^^^
AssertionError: Status code 204 must not have a response body
